Workbook

Sheet Wil 1
A1: WILAYAH 1; LAPORAN PENJUALAN BENUR VANNAMEI BULAN JANUARI 2023
A3: NO | B3: NAMA NASABAH | C3: NOMOR KONTAK | D3: ALAMAT | E3: TUJUAN BENUR | F3: KETERANGAN | G3: MINGGU | K3: TOTAL
G4: PERTAMA | H4: KE DUA | I4: KE TIGA | J4: KE EMPAT
A5: PINRANG | G5: TGL 1 S/D 7 | H5: TGL 8 S/D 14 | I5: TGL 15 S/D 21 | J5: TGL 22 S/D 31
A6: 1 | B6: ANDI ACO | C6: 082 320147066 | D6: PINRANG | E6: PINRANG | F6: PETAMBAK | G6: 55200 | H6: 0 | I6: 0 | J6: 0 | K6: =SUM(G6:J6) -> 55200
A7: 2 | B7: AWAL/SUKRI | C7: 085 242239100 | D7: BARRU | E7: PINRANG | F7: DISTRIBUTOR | G7: 56000 | H7: 0 | I7: 0 | J7: 0 | K7: =SUM(G7:J7) -> 56000
A8: 3 | B8: HJ.NASI/GM | C8: 085 343738258 | D8: PINRANG | E8: PINRANG | F8: PETAMBAK | G8: 56000 | H8: 0 | I8: 0 | J8: 0 | K8: =SUM(G8:J8) -> 56000
A9: 4 | B9: SYARIFUDDIN | C9: 082 353208502 | D9: PINRANG | E9: PINRANG | F9: PETAMBAK | G9: 55200 | H9: 0 | I9: 0 | J9: 44000 | K9: =SUM(G9:J9) -> 99200
A10: 5 | B10: BURHAN/OGGO | C10: 082 216063537 | D10: PINRANG | E10: PINRANG | F10: KORD/DISTRIBUTOR | G10: 717600 | H10: 385000 | I10: 110000 | J10: 937000 | K10: =SUM(G10:J10) -> 2149600
A11: 6 | B11: SITTIARAH | C11: 085 255338177 | D11: PINRANG | E11: PINRANG | F11: PETAMBAK | G11: 188000 | H11: 0 | I11: 188000 | J11: 0 | K11: =SUM(G11:J11) -> 376000
A12: 7 | B12: H.DULLAH | C12: 082 394243270 | D12: PINRANG | E12: PINRANG | F12: KORD/DISTRIBUTOR | G12: 328000 | H12: 0 | I12: 0 | J12: 110000 | K12: =SUM(G12:J12) -> 438000
A13: 8 | B13: BURHAN/YUHAR | C13: 085 298573833 | D13: MALILI | E13: PINRANG | F13: KORD/DISTRIBUTOR | G13: 165600 | H13: 165600 | I13: 0 | J13: 0 | K13: =SUM(G13:J13) -> 331200
A14: 9 | B14: ACO/JUFRI | C14: 085 256408867 | D14: PINRANG | E14: PINRANG | F14: PETAMBAK | G14: 440000 | H14: 0 | I14: 441600 | J14: 440000 | K14: =SUM(G14:J14) -> 1321600
A15: 10 | B15: SYARIF KORSEK | C15: 082 398779456 | D15: PINRANG | E15: PINRANG | F15: KORD/DISTRIBUTOR | H15: 25300 | I15: 0 | J15: 11500 | K15: =SUM(G15:J15) -> 36800
A16: 11 | B16: LATANG | D16: PINRANG | E16: PINRANG | F16: PETAMBAK | H16: 46000 | I16: 0 | J16: 0 | K16: =SUM(G16:J16) -> 46000
A17: 12 | B17: BURHAN | C17: 085 299202872 | D17: MALILI | E17: PINRANG | F17: KORD/DISTRIBUTOR | H17: 276000 | I17: 110400 | J17: 386400 | K17: =SUM(G17:J17) -> 772800
A18: 13 | B18: ACA | D18: PINRANG | E18: PINRANG | F18: PETAMBAK | H18: 6000 | I18: 0 | J18: 0 | K18: =SUM(G18:J18) -> 6000
A19: 14 | B19: RISWAN | C19: 085 145621835 | D19: PINRANG | E19: PINRANG | F19: PETAMBAK | H19: 55000 | I19: 0 | J19: 0 | K19: =SUM(G19:J19) -> 55000
A20: 15 | B20: ANDI GANEFO | D20: PINRANG | E20: PINRANG | F20: PETAMBAK | H20: 77500 | I20: 0 | J20: 0 | K20: =SUM(G20:J20) -> 77500
A21: 16 | B21: EDI ALI | D21: PINRANG | E21: PINRANG | F21: PETAMBAK | I21: 110400 | J21: 0 | K21: =SUM(G21:J21) -> 110400
A22: 17 | B22: ANDI RAKA | D22: PINRANG | E22: PINRANG | F22: PETAMBAK | I22: 110000 | J22: 0 | K22: =SUM(G22:J22) -> 110000
A23: 18 | B23: RUDI | D23: PINRANG | E23: PINRANG | F23: PETAMBAK | J23: 55200 | K23: =SUM(G23:J23) -> 55200
A24: 19 | B24: BURHAN/UMAR | D24: MALILI | E24: PINRANG | F24: KORD/DISTRIBUTOR | J24: 220000 | K24: =SUM(G24:J24) -> 220000
A25: 20 | B25: SAPRI | D25: PINRANG | E25: PINRANG | F25: PETAMBAK | J25: 264500 | K25: =SUM(G25:J25) -> 264500
A26: 21 | B26: BURHAN/AIDIL | D26: MALILI | E26: PINRANG | F26: KORD/DISTRIBUTOR | J26: 331200 | K26: =SUM(G26:J26) -> 331200
A27: 22 | B27: MANSYUR/SAHAR | D27: BARRU | E27: PINRANG | F27: KORD/DISTRIBUTOR | J27: 40000 | K27: =SUM(G27:J27) -> 40000
A28: 23 | B28: ANTO | D28: PINRANG | E28: PINRANG | F28: PETAMBAK | J28: 34500 | K28: =SUM(G28:J28) -> 34500
A29: 24 | B29: A.DARSO | D29: PINRANG | E29: PINRANG | F29: KORD/DISTRIBUTOR | J29: 440000 | K29: =SUM(G29:J29) -> 440000
A30: TOTAL | G30: =SUM(G6:G29) -> 2061600 | H30: =SUM(H6:H29) -> 1036400 | I30: =SUM(I6:I29) -> 1070400 | J30: =SUM(J6:J29) -> 3314300 | K30: =SUM(G30:J30) -> 7482700
A31: POLMAN
A32: 1 | B32: HALIM | C32: 081 383734465 | D32: POLMAN | E32: POLMAN | F32: KORD/DISTRIBUTOR | G32: 232000 | H32: 212000 | I32: 192500 | J32: 872000 | K32: =SUM(G32:J32) -> 1508500
A33: 2 | B33: AMIRUDDIN | C33: 0811 426173 | D33: POLMAN | E33: POLMAN | F33: KORD/DISTRIBUTOR | G33: 1042000 | H33: 1014800 | I33: 623300 | J33: 837700 | K33: =SUM(G33:J33) -> 3517800
A34: 3 | B34: USMAN | C34: 085 255893129 | D34: POLMAN | E34: POLMAN | F34: KORD/DISTRIBUTOR | G34: 276000 | H34: 0 | I34: 0 | J34: 308000 | K34: =SUM(G34:J34) -> 584000
A35: 4 | B35: USMAN/ALGI | C35: 085 255893129 | D35: POLMAN | E35: POLMAN | F35: KORD/DISTRIBUTOR | H35: 121900 | I35: 0 | J35: 0 | K35: =SUM(G35:J35) -> 121900
A36: 5 | B36: H.FADLY | C36: 081 24156669 | D36: POLMAN | E36: POLMAN | F36: KORD/DISTRIBUTOR | H36: 200100 | I36: 0 | J36: 341300 | K36: =SUM(G36:J36) -> 541400
A37: 6 | B37: ABD.GAFFAR | C37: 085 210638079 | D37: POLMAN | E37: POLMAN | F37: PETAMBAK | H37: 23000 | I37: 0 | J37: 0 | K37: =SUM(G37:J37) -> 23000
A38: 7 | B38: USMAN/RAFLI | C38: 085 255893129 | D38: POLMAN | E38: POLMAN | F38: KORD/DISTRIBUTOR | H38: 308000 | I38: 616000 | J38: 616200 | K38: =SUM(G38:J38) -> 1540200
A39: 8 | B39: SAPRI | C39: 081 242988456 | D39: POLMAN | E39: POLMAN | F39: PENGGELONDONG | H39: 342500 | I39: 0 | J39: 330000 | K39: =SUM(G39:J39) -> 672500
A40: 9 | B40: KARTINI | C40: 085 299348553 | D40: POLMAN | E40: POLMAN | F40: PETAMBAK | H40: 55000 | I40: 0 | J40: 0 | K40: =SUM(G40:J40) -> 55000
A41: 10 | B41: USMAN/H.DARWIS | C41: 085 255893129 | D41: POLMAN | E41: POLMAN | F41: KORD/DISTRIBUTOR | H41: 220800 | I41: 0 | J41: 0 | K41: =SUM(G41:J41) -> 220800
...

Sheet Wil 2
A1: WILAYAH 2; LAPORAN PENJUALAN BENUR VANNAMEI BULAN JANUARI 2023
A3: NO | B3: NAMA NASABAH | C3: NOMOR KONTAK | D3: ALAMAT | E3: TUJUAN BENUR | F3: KETERANGAN | G3: MINGGU | K3: TOTAL
G4: PERTAMA | H4: KE DUA | I4: KE TIGA | J4: KE EMPAT
A5: PARE-PARE | G5: TGL 1 S/D 7 | H5: TGL 8 S/D 14 | I5: TGL 15 S/D 21 | J5: TGL 22 S/D 31
A6: 1 | B6: H.MUH.TAHIR | C6: 081 342154521 | D6: PARE-PARE | E6: PARE-PARE | F6: PETAMBAK | H6: 66700 | K6: =SUM(G6:J6) -> 66700
A7: TOTAL | G7: =SUM(G6:G6) -> 0 | H7: =SUM(H6:H6) -> 66700 | I7: =SUM(I6:I6) -> 0 | J7: =SUM(J6:J6) -> 0 | K7: =SUM(G7:J7) -> 66700
A8: BARRU
A9: 1 | B9: RAMAYANA | D9: BARRU | E9: BARRU | F9: PETAMBAK | H9: 23000 | I9: 0 | J9: 0 | K9: =SUM(G9:J9) -> 23000
A10: 2 | B10: ASDAR | D10: BARRU | E10: BARRU | F10: PETAMBAK | H10: 23000 | I10: 0 | J10: 0 | K10: =SUM(G10:J10) -> 23000
A11: 3 | B11: RISWAN | C11: 085 145621835 | D11: BARRU | E11: BARRU | F11: PETAMBAK | H11: 20700 | I11: 55500 | J11: 20700 | K11: =SUM(G11:J11) -> 96900
A12: 4 | B12: MANSYUR/SAHAR | C12: 082 350717772 | D12: BARRU | E12: BARRU | F12: KORD/DISTRIBUTOR | H12: 11500 | I12: 291700 | J12: 312800 | K12: =SUM(G12:J12) -> 616000
A13: 5 | B13: YUSRAN | D13: BARRU | E13: BARRU | F13: PETAMBAK | H13: 18400 | I13: 0 | J13: 0 | K13: =SUM(G13:J13) -> 18400
A14: 6 | B14: SIRAJUDDIN | C14: 085 342257852 | D14: BARRU | E14: BARRU | F14: PETAMBAK | H14: 22500 | I14: 27600 | J14: 27500 | K14: =SUM(G14:J14) -> 77600
A15: 7 | B15: ZULKIFLI | D15: BARRU | E15: BARRU | F15: PETAMBAK | H15: 27500 | I15: 0 | J15: 0 | K15: =SUM(G15:J15) -> 27500
A16: 8 | B16: TALIB | D16: BARRU | E16: BARRU | F16: PETAMBAK | H16: 46000 | I16: 0 | J16: 0 | K16: =SUM(G16:J16) -> 46000
A17: 9 | B17: HASRAN | C17: 082 187970562 | D17: BARRU | E17: BARRU | F17: PETAMBAK | H17: 11500 | I17: 30000 | J17: 0 | K17: =SUM(G17:J17) -> 41500
A18: 10 | B18: H.HANISI | D18: BARRU | E18: BARRU | F18: PETAMBAK | I18: 46000 | J18: 0 | K18: =SUM(G18:J18) -> 46000
A19: 11 | B19: M.SALENG | D19: BARRU | E19: BARRU | F19: PETAMBAK | I19: 34500 | J19: 0 | K19: =SUM(G19:J19) -> 34500
A20: 12 | B20: SULAEMAN | C20: 085 340654153 | D20: BARRU | E20: BARRU | F20: PETAMBAK | I20: 15000 | J20: 0 | K20: =SUM(G20:J20) -> 15000
A21: 13 | B21: RANDI | D21: BARRU | E21: BARRU | F21: PETAMBAK | I21: 17500 | J21: 0 | K21: =SUM(G21:J21) -> 17500
A22: 14 | B22: SUDIRMAN | C22: 085 256385388 | D22: BARRU | E22: BARRU | F22: PETAMBAK | I22: 30000 | J22: 0 | K22: =SUM(G22:J22) -> 30000
A23: 15 | B23: ABD.SAFAR | D23: BARRU | E23: BARRU | F23: PETAMBAK | I23: 22000 | J23: 0 | K23: =SUM(G23:J23) -> 22000
A24: 16 | B24: ZUL | D24: BARRU | E24: BARRU | F24: PETAMBAK | I24: 0 | J24: 23000 | K24: =SUM(G24:J24) -> 23000
A25: 17 | B25: KAMINUDDIN | D25: BARRU | E25: BARRU | F25: PETAMBAK | J25: 23000 | K25: =SUM(G25:J25) -> 23000
A26: 18 | B26: NASARUDDIN | D26: BARRU | E26: BARRU | F26: PETAMBAK | J26: 6900 | K26: =SUM(G26:J26) -> 6900
A27: 19 | B27: BAHAR/H.BAHAR | D27: BARRU | E27: BARRU | F27: PETAMBAK | J27: 55200 | K27: =SUM(G27:J27) -> 55200
A28: 20 | B28: AKBAR | D28: BARRU | E28: BARRU | F28: PETAMBAK | J28: 55200 | K28: =SUM(G28:J28) -> 55200
A29: 21 | B29: ASRI | D29: BARRU | E29: BARRU | F29: PETAMBAK | J29: 39100 | K29: =SUM(G29:J29) -> 39100
A30: 22 | B30: JALIL | D30: BARRU | E30: BARRU | F30: PETAMBAK | J30: 39100 | K30: =SUM(G30:J30) -> 39100
A31: 23 | B31: ANWAR | D31: BARRU | E31: BARRU | F31: PETAMBAK | J31: 28000 | K31: =SUM(G31:J31) -> 28000
A32: 24 | B32: RISAL | D32: BARRU | E32: BARRU | F32: PETAMBAK | J32: 28000 | K32: =SUM(G32:J32) -> 28000
A33: 25 | B33: H.FATTA | D33: BARRU | E33: BARRU | F33: PETAMBAK | J33: 1872200 | K33: =SUM(G33:J33) -> 1872200
A34: 26 | B34: H.RUSLI | D34: BARRU | E34: BARRU | F34: PETAMBAK | J34: 105800 | K34: =SUM(G34:J34) -> 105800
A35: 27 | B35: FAISAL | D35: BARRU | E35: BARRU | F35: PETAMBAK | J35: 50000 | K35: =SUM(G35:J35) -> 50000
A36: 28 | B36: ERWIN | D36: BARRU | E36: BARRU | F36: PETAMBAK | J36: 11500 | K36: =SUM(G36:J36) -> 11500
... A45: 37 | B45: NOLLENG | D45: BARRU | E45: BARRU | F45: PETAMBAK | J45: 17500 | K45: =SUM(G45:J45) -> 17500
A46: TOTAL | G46: =SUM(G9:G45) -> 0 | H46: =SUM(H9:H45) -> 204100 | I46: =SUM(I9:I45) -> 569800 | J46: =SUM(J9:J45) -> 3358800 | K46: =SUM(G46:J46) -> 4132700
A47: PANGKEP
A48: 1 | B48: AMRULLAH | C48: 085 255201886 | D48: PANGKEP | E48: PANGKEP | F48: KORD/PENGGELONDONG | G48: 386000 | H48: 0 | I48: 972000 | J48: 690000 | K48: =SUM(G48:J48) -> 2048000
A49: 2 | B49: AHMAD | C49: 082 344015485 | D49: PANGKEP | E49: PANGKEP | F49: PETAMBAK | G49: 101200 | H49: 0 | I49: 46000 | J49: 0 | K49: =SUM(G49:J49) -> 147200
...

Sheet MP
A1: DIRECT ORDER; LAPORAN PENJUALAN BENUR VANNAMEI BULAN JANUARI 2023
A3: NO | B3: NAMA NASABAH | C3: ALAMAT | D3: TUJUAN BENUR | E3: MINGGU | I3: TOTAL
E4: PERTAMA | F4: KEDUA | G4: KETIGA | H4: KEEMPAT
A5: JAWA & SUMATRA | E5: TGL 1 S/D 7 | F5: TGL 8 S/D 14 | G5: TGL 15 S/D 21 | H5: TGL 22 S/D 31
A6: 1 | B6: ROKHIMAN | C6: YOGYAKARTA | D6: YOGYAKARTA | E6: 530000 | F6: 275000 | G6: 310000 | H6: 0 | I6: =SUM(E6:H6) -> 1115000
A7: 2 | B7: SUYONO | C7: YOGYAKARTA | D7: YOGYAKARTA | E7: 1100000 | F7: 880000 | G7: 2450000 | H7: 1685000 | I7: =SUM(E7:H7) -> 6115000
A8: 3 | B8: INDRA YUDIANTO | C8: BALIKPAPAN | D8: BALIKPAPAN | E8: 55000 | F8: 0 | G8: 0 | H8: 0 | I8: =SUM(E8:H8) -> 55000
A9: 4 | B9: AJI DARMAJI | C9: YOGYAKARTA | D9: YOGYAKARTA | F9: 210000 | G9: 0 | H9: 0 | I9: =SUM(E9:H9) -> 210000
A10: 5 | B10: HERMANTO | C10: BENGKALIS | D10: BENGKALIS | F10: 1355000 | G10: 1980000 | H10: 1650000 | I10: =SUM(E10:H10) -> 4985000
A11: 6 | B11: RIDWAN BASUKI | C11: YOGYAKARTA | D11: YOGYAKARTA | F11: 300000 | G11: 350000 | H11: 0 | I11: =SUM(E11:H11) -> 650000
A12: 7 | B12: ROZIKIN | C12: YOGYAKARTA | D12: YOGYAKARTA | G12: 330000 | H12: 0 | I12: =SUM(E12:H12) -> 330000
A13: 8 | B13: MATAMAQIN | C13: SEMARANG | D13: SEMARANG | H13: 110000 | I13: =SUM(E13:H13) -> 110000
A14: 9 | B14: EKO AGUNG PURNAMA | C14: YOGYAKARTA | D14: YOGYAKARTA | H14: 200000 | I14: =SUM(E14:H14) -> 200000
A15: 10 | B15: MAULANA MUKHLIS | C15: YOGYAKARTA | D15: YOGYAKARTA | H15: 1882500 | I15: =SUM(E15:H15) -> 1882500
A16: 11 | B16: SAWON | C16: YOGYAKARTA | D16: YOGYAKARTA | H16: 462500 | I16: =SUM(E16:H16) -> 462500
A17: TOTAL | E17: =SUM(E6:E16) -> 1685000 | F17: =SUM(F6:F16) -> 3020000 | G17: =SUM(G6:G16) -> 5420000 | H17: =SUM(H6:H16) -> 5990000 | I17: =SUM(E17:H17) -> 16115000
A18: KALIMANTAN,MALUKU & PAPUA
A19: 1 | B19: ANDI ERWIN | C19: BARRU | D19: BONTANG | E19: 716000 | F19: 1320000 | G19: 0 | H19: 0 | I19: =SUM(E19:H19) -> 2036000
A20: 2 | B20: SAPMARNA | C20: BARRU | D20: KALSEL | F20: 220000 | G20: 165000 | H20: 220000 | I20: =SUM(E20:H20) -> 605000
A21: 3 | B21: SAIDIN | C21: SORONG | D21: SORONG | H21: 165000 | I21: =SUM(E21:H21) -> 165000
A22: 4 | B22: SAPMARNA | C22: BARRU | D22: KALTIM | H22: 320000 | I22: =SUM(E22:H22) -> 320000
A23: TOTAL | E23: =SUM(E19:E22) -> 716000 | F23: =SUM(F19:F22) -> 1540000 | G23: =SUM(G19:G22) -> 165000 | H23: =SUM(H19:H22) -> 705000 | I23: =SUM(E23:H23) -> 3126000
A24: GRAND TOTAL | E24: =E17+E23 -> 2401000 | F24: =F17+F23 -> 4560000 | G24: =G17+G23 -> 5585000 | H24: =H17+H23 -> 6695000 | I24: =SUM(E24:H24) -> 19241000
A26: TOTAL PENJUALAN BULAN JANUARI 2023 : | D26: =SUM(D27:D31) -> 359084300
A27: 1. | B27: WILAYAH 1 | D27: ='Wil 1'!K192 -> 170634300 | G27: Jalange', 01 Februari 2023
A28: 2. | B28: WILAYAH 2 | D28: ='Wil 2'!K380 -> 131651700
A29: 3. | B29: ANTAR PULAU | D29: =I24 -> 19241000
A30: 4. | B30: SATELIT | D30: ='Wil 1'!E198 -> 16280000
A31: 5. | B31: TAMBAK EPU | D31: ='Wil 1'!E199 -> 21277300
A32: 6. | B32: CASHBACK | D32: 0
A33: 7. | B33: PERGANTIAN | D33: 0 | G33: HIDAYAT SYAH
A34: TOTAL PRODUKSI BULAN JANUARI 2023: | D34: =SUM(D27:D33) -> 359084300 | G34: Manager Sales & Delivery

Sheet Nener
A1: PENJUALAN NENER BULAN JANUARI 2023
A3: NO | B3: NAMA NASABAH | C3: ALAMAT | D3: TUJUAN | E3: KETERANGAN | F3: MINGGU | J3: TOTAL
F4: MINGGU I | G4: MINGGU II | H4: MINGGU III | I4: MINGGU IV
A5: PINRANG | F5: TGL 1 S/D 7 | G5: TGL 8 S/D 14 | H5: TGL 15 S/D 21 | I5: TGL 22 S/D 31
A6: 1 | B6: AMBO ANNU | C6: PINRANG | D6: PINRANG | E6: PENGGELONDONG | F6: 56000 | G6: 103000 | I6: 158500 | J6: =SUM(F6:I6) -> 317500
A7: 2 | B7: AHMAD | C7: PINRANG | D7: PINRANG | E7: PETAMBAK | F7: 2000 | J7: =SUM(F7:I7) -> 2000
A8: 3 | B8: ALI | C8: PINRANG | D8: PINRANG | E8: PENGGELONDONG | F8: 110000 | G8: 70000 | I8: 162000 | J8: =SUM(F8:I8) -> 342000
A9: 4 | B9: IBRAHIM | C9: PINRANG | D9: PINRANG | E9: PETAMBAK | F9: 20000 | J9: =SUM(F9:I9) -> 20000
A10: 5 | B10: IPATI | C10: PINRANG | D10: PINRANG | E10: PENGGELONDONG | F10: 80000 | H10: 55000 | I10: 100000 | J10: =SUM(F10:I10) -> 235000
A11: 6 | B11: PN BASRI | C11: PINRANG | D11: PINRANG | E11: PENGGELONDONG | F11: 100000 | I11: 100000 | J11: =SUM(F11:I11) -> 200000
A12: 7 | B12: SUDIRMAN Data | C12: PINRANG | D12: PINRANG | E12: PENGGELONDONG | F12: 50000 | G12: 50000 | H12: 130000 | I12: 250000 | J12: =SUM(F12:I12) -> 480000
A13: 8 | B13: H.MUHAMMAD | C13: PINRANG | D13: PINRANG | E13: PENGGELONDONG | F13: 50000 | I13: 60000 | J13: =SUM(F13:I13) -> 110000
A14: 9 | B14: SITTIARA | C14: PINRANG | D14: PINRANG | E14: PENGGELONDONG | F14: 50000 | I14: 70000 | J14: =SUM(F14:I14) -> 120000
A15: 10 | B15: BURHAN/OGGO | C15: PINRANG | D15: PINRANG | E15: PENGGELONDONG | F15: 30000 | I15: 130000 | J15: =SUM(F15:I15) -> 160000
A16: 11 | B16: MUSTAMIN | C16: PINRANG | D16: PINRANG | E16: PETAMBAK | F16: 4000 | J16: =SUM(F16:I16) -> 4000
A17: 12 | B17: ASRI | C17: PINRANG | D17: PINRANG | E17: PETAMBAK | G17: 50000 | J17: =SUM(F17:I17) -> 50000
A18: 13 | B18: ABDULLAH | C18: PINRANG | D18: PINRANG | E18: PETAMBAK | G18: 10000 | J18: =SUM(F18:I18) -> 10000
A19: 14 | B19: RAHMAN YATO | C19: PINRANG | D19: PINRANG | E19: PETAMBAK | G19: 10000 | J19: =SUM(F19:I19) -> 10000
A20: 15 | B20: DG KALLO | C20: PINRANG | D20: PINRANG | E20: PENGGELONDONG | G20: 50000 | I20: 40000 | J20: =SUM(F20:I20) -> 90000
A21: 16 | B21: ANDI PATURUSI | C21: PINRANG | D21: PINRANG | E21: PETAMBAK | G21: 10000 | J21: =SUM(F21:I21) -> 10000
A22: 17 | B22: HJ.JASA | C22: PINRANG | D22: PINRANG | E22: PENGGELONDONG | H22: 50000 | J22: =SUM(F22:I22) -> 50000
A23: 18 | B23: AWAL/SUKRI | C23: BARRU | D23: PINRANG | E23: DISTRIBUTOR | I23: 18000 | J23: =SUM(F23:I23) -> 18000
A24: 19 | B24: DODING/WAHAB | C24: PINRANG | D24: PINRANG | E24: PENGGELONDONG | I24: 20000 | J24: =SUM(F24:I24) -> 20000
A25: 20 | B25: ABDULLAH | C25: PINRANG | D25: PINRANG | E25: PETAMBAK | I25: 30000 | J25: =SUM(F25:I25) -> 30000
A26: 21 | B26: ACO/JUFRI | C26: PINRANG | D26: PINRANG | E26: PENGGELONDONG | I26: 70000 | J26: =SUM(F26:I26) -> 70000
A27: 22 | B27: WAHYU | C27: PINRANG | D27: PINRANG | E27: PENGGELONDONG | I27: 50000 | J27: =SUM(F27:I27) -> 50000
A28: 23 | B28: SURYANTI | C28: PINRANG | D28: PINRANG | E28: PETAMBAK | I28: 15000 | J28: =SUM(F28:I28) -> 15000
A29: 24 | B29: AZIS/GM | C29: PINRANG | D29: PINRANG | E29: PENGGELONDONG | I29: 70000 | J29: =SUM(F29:I29) -> 70000
A30: 25 | B30: BURHAN | C30: PINRANG | D30: PINRANG | E30: PETAMBAK | I30: 15000 | J30: =SUM(F30:I30) -> 15000
A31: 26 | B31: HJ.ROSMIATI | C31: PINRANG | D31: PINRANG | E31: PETAMBAK | I31: 16500 | J31: =SUM(F31:I31) -> 16500
A32: 27 | B32: A.DARSO | C32: PINRANG | D32: PINRANG | E32: DISTRIBUTOR | I32: 100000 | J32: =SUM(F32:I32) -> 100000
A33: TOTAL | F33: =SUM(F6:F32) -> 552000 | G33: =SUM(G6:G32) -> 353000 | H33: =SUM(H6:H32) -> 235000 | I33: =SUM(I6:I32) -> 1475000 | J33: =SUM(J6:J32) -> 2615000
A34: POLMAN & MAJENE
A35: 1 | B35: H.DAHLAN | C35: POLMAN | D35: POLMAN | E35: PETAMBAK | F35: 15000 | I35: 45000 | J35: =SUM(F35:I35) -> 60000
A36: 2 | B36: AMIRUDDIN | C36: POLMAN | D36: POLMAN | E36: DISTRIBUTOR | F36: 5000 | H36: 51500 | I36: 220000 | J36: =SUM(F36:I36) -> 276500
A37: 3 | B37: ABD GAFFAR/KARTINI | C37: POLMAN | D37: POLMAN | E37: DISTRIBUTOR | G37: 6000 | I37: 65000 | J37: =SUM(F37:I37) -> 71000
A38: 4 | B38: HALIM | C38: POLMAN | D38: POLMAN | E38: DISTRIBUTOR | G38: 12000 | I38: 10000 | J38: =SUM(F38:I38) -> 22000
A39: 5 | B39: SAHIDIN | C39: POLMAN | D39: POLMAN | E39: PENGGELONDONG | H39: 70000 | I39: 105000 | J39: =SUM(F39:I39) -> 175000
A40: 6 | B40: MURSAM | C40: POLMAN | D40: POLMAN | E40: PENGGELONDONG | I40: 50000 | J40: =SUM(F40:I40) -> 50000
A41: 7 | B41: SUPRI | C41: POLMAN | D41: POLMAN | E41: PENGGELONDONG | I41: 150000 | J41: =SUM(F41:I41) -> 150000
...

Sheet Tabulasi Harian
A1: TABULASI PENJUALAN HARIAN PERIODE JANUARI 2023
A3: NO | B3: HARI/TANGGAL | C3: WILAYAH 1 | D3: WILAYAH 2 | E3: D. ORDER | F3: TAMBAK EPU | G3: SATELIT | H3: TOTAL | I3: CASHBACK | J3: PERGANTIAN | K3: ALLOWANCE | L3: TOTAL PRODUKSI | M3: UNIT 1 | N3: UNIT 2 | O3: UNIT 3 | P3: UNIT 4
H4: PENJUALAN
A5: 1 | B5: 44927 | C5: 352000 | D5: 2769300 | H5: =SUM(C5:G5) -> 3121300 | K5: 279300 | L5: =SUM(H5:J5) -> 3121300 | M5: 1024500 | N5: 2096800
A6: 2 | B6: 44928 | C6: 2110400 | D6: 4524300 | E6: 220000 | F6: 1750300 | G6: 1780000 | H6: =SUM(C6:G6) -> 10385000 | K6: 648000 | L6: =SUM(H6:J6) -> 10385000 | M6: 56000 | N6: 10329000
A7: 3 | B7: 44929 | C7: 3251000 | D7: 2731700 | G7: 2000000 | H7: =SUM(C7:G7) -> 7982700 | K7: 567700 | L7: =SUM(H7:J7) -> 7982700 | M7: 1987600 | N7: 4921000 | P7: 1074100
A8: 4 | B8: 44930 | C8: 2557700 | D8: 4799100 | F8: 1800900 | H8: =SUM(C8:G8) -> 9157700 | K8: 702519 | L8: =SUM(H8:J8) -> 9157700 | M8: 4323400 | N8: 2312000 | P8: 2522300
A9: 5 | B9: 44931 | C9: 5154300 | D9: 2897900 | E9: 1155000 | H9: =SUM(C9:G9) -> 9207200 | K9: 852200 | L9: =SUM(H9:J9) -> 9207200 | P9: 9207200
A10: 6 | B10: 44932 | C10: 6334800 | D10: 3773300 | F10: 1750300 | H10: =SUM(C10:G10) -> 11858400 | K10: 860946 | L10: =SUM(H10:J10) -> 11858400 | M10: 9233100 | N10: 2625300
A11: 7 | B11: 44933 | C11: 9009000 | D11: 5160200 | E11: 1026000 | H11: =SUM(C11:G11) -> 15195200 | K11: 1397200 | L11: =SUM(H11:J11) -> 15195200 | M11: 3987500 | N11: 3889200 | P11: 7318500
A12: JUMLAH | C12: =SUM(C5:C11) -> 28769200 | D12: =SUM(D5:D11) -> 26655800 | E12: =SUM(E5:E11) -> 2401000 | F12: =SUM(F5:F11) -> 5301500 | G12: =SUM(G5:G11) -> 3780000 | H12: =SUM(H5:H11) -> 66907500 | I12: =SUM(I5:I11) -> 0 | J12: =SUM(J5:J11) -> 0 | ... P12: =SUM(P5:P11) -> 20122100
A13: 1 | B13: 44569 | C13: 9411100 | D13: 3267100 | H13: =SUM(C13:G13) -> 12678200 | K13: 1181110 | L13: =SUM(H13:J13) -> 12678200 | M13: 4062500 | N13: 59800 | O13: 517500 | P13: 8038400
A14: 2 | B14: 44570 | C14: 3855900 | D14: 4329800 | G14: 2200000 | H14: =SUM(C14:G14) -> 10385700 | I14: 87000 | K14: 813200 | L14: =SUM(H14:J14) -> 10472700 | M14: 2218000 | O14: 3677700 | P14: 4490000
A15: 3 | B15: 44571 | C15: 11333200 | D15: 3020700 | E15: 1310000 | G15: 1500000 | H15: =SUM(C15:G15) -> 17163900 | I15: 220500 | J15: 150000 | K15: 1443600 | L15: =SUM(H15:J15) -> 17534400 | M15: 4341600 | N15: 7270000 | O15: 156300 | P15: 5396000
A16: 4 | B16: 44572 | C16: 4674300 | D16: 3281900 | E16: 2975000 | H16: =SUM(C16:G16) -> 10931200 | I16: 88700 | K16: 1031200 | L16: =SUM(H16:J16) -> 11019900 | M16: 5615800 | O16: 2385400 | P16: 2930000
A17: 5 | B17: 44573 | C17: 7830000 | D17: 3916700 | F17: 1800900 | H17: =SUM(C17:G17) -> 13547600 | I17: 63000 | K17: 1077600 | L17: =SUM(H17:J17) -> 13610600 | M17: 4749200 | N17: 2220900 | O17: 6577500
A18: 6 | B18: 44574 | C18: 5784900 | D18: 3826900 | H18: =SUM(C18:G18) -> 9611800 | K18: 892800 | L18: =SUM(H18:J18) -> 9611800 | M18: 4429300 | N18: 5182500
A19: 7 | B19: 44575 | C19: 2559500 | D19: 2090100 | E19: 275000 | F19: 1750300 | H19: =SUM(C19:G19) -> 6674900 | K19: 463900 | L19: =SUM(H19:J19) -> 6674900 | M19: 2264200 | N19: 4410700
A20: JUMLAH | C20: =SUM(C13:C19) -> 45448900 | D20: =SUM(D13:D19) -> 23733200 | E20: =SUM(E13:E19) -> 4560000 | F20: =SUM(F13:F19) -> 3551200 | G20: =SUM(G13:G19) -> 3700000 | H20: =SUM(H13:H19) -> 80993300 | I20: =SUM(I13:I19) -> 459200 | J20: =SUM(J13:J19) -> 150000 | ... P20: =SUM(P13:P19) -> 20854400
A21: 1 | B21: 44576 | C21: 1413800 | D21: 1748000 | E21: 1877500 | H21: =SUM(C21:G21) -> 5039300 | K21: 472800 | L21: =SUM(H21:J21) -> 5039300 | M21: 1032700 | N21: 4006600
A22: 2 | B22: 44577 | C22: 1552900 | D22: 5152700 | E22: 1980000 | F22: 1800900 | H22: =SUM(C22:G22) -> 10486500 | I22: 170500 | K22: 834000 | L22: =SUM(H22:J22) -> 10657000 | N22: 7172200 | O22: 3314300
A23: 3 | B23: 44578 | C23: 2955900 | D23: 6995700 | E23: 165000 | G23: 2200000 | H23: =SUM(C23:G23) -> 12316600 | K23: 936480 | L23: =SUM(H23:J23) -> 12316600 | M23: 4502500 | N23: 6496300 | O23: 1317800
A24: 4 | B24: 44579 | C24: 6913600 | D24: 7482100 | E24: 310000 | F24: 1750300 | H24: =SUM(C24:G24) -> 16456000 | I24: 540000 | K24: 1383774 | L24: =SUM(H24:J24) -> 16996000 | N24: 6706400 | O24: 5294600 | P24: 4455000
A25: 5 | B25: 44580 | C25: 940700 | D25: 3005600 | E25: 330000 | F25: 4142300 | G25: 2200000 | H25: =SUM(C25:G25) -> 10618600 | J25: 9500 | K25: 403600 | L25: =SUM(H25:J25) -> 10628100 | M25: 2774000 | O25: 3721300 | P25: 4123300
A26: 6 | B26: 44581 | C26: 7447500 | D26: 5604200 | H26: =SUM(C26:G26) -> 13051700 | I26: 448000 | K26: 1232700 | L26: =SUM(H26:J26) -> 13499700 | M26: 2016200 | O26: 10683000 | P26: 352500
A27: 7 | B27: 44582 | C27: 1524500 | D27: 4420800 | E27: 922500 | H27: =SUM(C27:G27) -> 6867800 | I27: 232000 | J27: 326000 | K27: 649800 | L27: =SUM(H27:J27) -> 7425800 | M27: 2292000 | N27: 1937500 | O27: 2638300
A28: JUMLAH | C28: =SUM(C21:C27) -> 22748900 | D28: =SUM(D21:D27) -> 34409100 | E28: =SUM(E21:E27) -> 5585000 | F28: =SUM(F21:F27) -> 7693500 | G28: =SUM(G21:G27) -> 4400000 | H28: =SUM(H21:H27) -> 74836500 | I28: =SUM(I21:I27) -> 1390500 | J28: =SUM(J21:J27) -> 335500 | ... P28: =SUM(P21:P27) -> 8930800
A29: 1 | B29: 44583 | C29: 6101300 | D29: 3989600 | H29: =SUM(C29:G29) -> 10090900 | I29: 122000 | K29: 937900 | L29: =SUM(H29:J29) -> 10212900 | N29: 4787500 | O29: 4679400 | P29: 624000
A30: 2 | B30: 44584 | C30: 2907000 | D30: 9981700 | E30: 275000 | H30: =SUM(C30:G30) -> 13163700 | J30: 300000 | K30: 1252700 | L30: =SUM(H30:J30) -> 13463700 | N30: 6104000 | O30: 3561700 | P30: 3498000
A31: 3 | B31: 44585 | C31: 11391800 | D31: 2412900 | F31: 1423700 | H31: =SUM(C31:G31) -> 15228400 | J31: 8500 | K31: 1280900 | L31: =SUM(H31:J31) -> 15236900 | M31: 7527800 | N31: 3173300 | O31: 1972000 | P31: 2555300
A32: 4 | B32: 44586 | C32: 15154200 | D32: 5225800 | E32: 320000 | H32: =SUM(C32:G32) -> 20700000 | I32: 293000 | K32: 1860000 | L32: =SUM(H32:J32) -> 20993000 | M32: 5585900 | N32: 1798400 | O32: 7745000 | P32: 5570700
A33: 5 | B33: 44587 | C33: 10257100 | D33: 5437800 | E33: 1850000 | G33: 2200000 | H33: =SUM(C33:G33) -> 19744900 | I33: 296500 | K33: 1624400 | L33: =SUM(H33:J33) -> 20041400 | O33: 6855100 | P33: 12889800
A34: 6 | B34: 44588 | C34: 2412500 | D34: 4672600 | E34: 1882500 | H34: =SUM(C34:G34) -> 8967600 | K34: 853600 | L34: =SUM(H34:J34) -> 8967600 | M34: 3113200 | O34: 4461900 | P34: 1392500
A35: 7 | B35: 44589 | C35: 7080900 | D35: 301300 | E35: 462500 | H35: =SUM(C35:G35) -> 7844700 | K35: 729700 | L35: =SUM(H35:J35) -> 7844700 | O35: 3192200 | P35: 4652500
A36: 8 | B36: 44590 | C36: 11005800 | D36: 4431100 | E36: 220000 | F36: 1803200 | G36: 2200000 | H36: =SUM(C36:G36) -> 19660100 | K36: 1473600 | L36: =SUM(H36:J36) -> 19660100 | O36: 16138000 | P36: 3522100
A37: 9 | B37: 44591 | C37: 5707500 | D37: 7212000 | E37: 1685000 | H37: =SUM(C37:G37) -> 14604500 | K37: 1364500 | L37: =SUM(H37:J37) -> 14604500 | N37: 4800000 | O37: 2404500 | P37: 7400000
A38: 10 | B38: 44592 | C38: 1649200 | D38: 3188800 | F38: 1504200 | H38: =SUM(C38:G38) -> 6342200 | K38: 465200 | L38: =SUM(H38:J38) -> 6342200 | O38: 2019400 | P38: 4322800
A39: JUMLAH | C39: =SUM(C29:C38) -> 73667300 | D39: =SUM(D29:D38) -> 46853600 | E39: =SUM(E29:E38) -> 6695000 | F39: =SUM(F29:F38) -> 4731100 | G39: =SUM(G29:G38) -> 4400000 | H39: =SUM(H29:H38) -> 136347000 | I39: =SUM(I29:I38) -> 711500 | J39: =SUM(J29:J38) -> 308500 | K39: =SUM(K29:K38) -> 11842500 | L39: =C39+D39+E39+I39+J39+G39 -> 132635900 | M39: =SUM(M29:M38) -> 16226900 | N39: =SUM(N29:N38) -> 20663200 | O39: =SUM(O29:O38) -> 53029200 | P39: =SUM(P29:P38) -> 46427700
A40: GRAND TOTAL | C40: =C39+C28+C20+C12 -> 170634300 | D40: =D39+D28+D20+D12 -> 131651700 | E40: =E39+E28+E20+E12 -> 19241000 | F40: =F39+F28+F20+F12 -> 21277300 | G40: =G39+G28+G20+G12 -> 16280000 | H40: =SUM(C40:G40) -> 359084300 | I40: =I39+I28+I20+I12 -> 2561200 | J40: =J39+J28+J20+J12 -> 794000 | K40: =K39+K28+K20+K12 -> 29966929 | L40: =H40+I40+J40 -> 362439500 | M40: =M39+M28+M20+M12 -> 77137000 | N40: =N39+N28+N20+N12 -> 92299400 | O40: =O39+O28+O20+O12 -> 93312900 | P40: =P39+P28+P20+P12 -> 96335000
